<?xml version="1.0"?>
<robot xmlns:xacro="http://www.ros.org/wiki/xacro">

    <!-- Joints -->

    <joint name="base_footprint_joint" type="fixed">
        <parent link="base_footprint" />
        <child link="base_link" />
        <origin xyz="0.0 0.0 ${wheel_radius}" rpy="0.0 0.0 0.0" />
    </joint>

    <joint name="chassi_joint" type="fixed">
        <parent link="base_link" />
        <child link="chassi" />
        <origin xyz="0.0 0.0 0.0" rpy="0.0 0.0 0.0" />
    </joint>

    <joint name="body_joint" type="fixed">
        <parent link="chassi" />
        <child link="body" />
        <origin xyz="0.0 0.0 0.21" rpy="0.0 0.0 0.0" />
    </joint>


    <joint name="caster_1" type="fixed">
        <parent link="chassi" />
        <child link="caster_wheel_front" />
        <origin xyz="0.085 0.0 -0.016" rpy="0.0 0.0 0.0" />
    </joint>

    <joint name="caster_2" type="fixed">
        <parent link="chassi" />
        <child link="caster_wheel_rear" />
        <origin xyz="-0.085 0.0 -0.016" rpy="0.0 0.0 0.0" />
    </joint>


    <!-- Moving Joints-->

    <joint name="joint_1" type="continuous">
        <parent link="chassi" />
        <child link="right_wheel" />
        <axis xyz="0 0 1 " />
        <origin xyz="0 -0.11 0" rpy="-${pi/2} 0 0" />
    </joint>

    <joint name="joint_2" type="continuous">
        <parent link="chassi" />
        <child link="left_wheel" />
        <axis xyz="0 0 -1" />
        <origin xyz="0 0.11 0" rpy="${pi/2} 0 0" />
    </joint>

</robot>